<?xml version="1.0"?>
<robot name="two_joint_robot">
  <link name="base_link">
    <visual><geometry><box size="0.2 0.2 0.02"/></geometry></visual>
  </link>
  <link name="link1">
    <visual>
      <geometry><cylinder length="0.5" radius="0.03"/></geometry>
      <origin xyz="0 0 0.25" rpy="0 0 0"/>
    </visual>
  </link>
  <link name="link2">
    <visual>
      <geometry><cylinder length="0.4" radius="0.03"/></geometry>
      <origin xyz="0 0 0.2" rpy="0 0 0"/>
    </visual>
  </link>
  <joint name="joint1" type="revolute">
    <parent link="base_link"/>
    <child link="link1"/>
    <origin xyz="0 0 0.01" rpy="0 0 0"/>
    <axis xyz="0 1 0"/>
    <limit lower="-3.14" upper="3.14" effort="10" velocity="1"/>
  </joint>
  <joint name="joint2" type="revolute">
    <parent link="link1"/>
    <child link="link2"/>
    <origin xyz="0 0 0.5" rpy="0 0 0"/>
    <axis xyz="0 1 0"/>
    <limit lower="-3.14" upper="3.14" effort="10" velocity="1"/>
  </joint>
</robot>
